Workbook

Sheet Start
B1: MBA Platform · Midterm Project Template · Financial Statement Analysis
B2: قالب مشروع الميد تيرم: تحليل القوائم المالية لشركة
B4: HOW TO USE · طريقة الاستخدام
B5: 1. Go to the Input sheet. Replace the yellow cells (blue numbers) with your company's figures from its audited annual financial statements.
B6: روح على شيت Input، وغيّر الخانات الصفرا (الأرقام الزرقا) بأرقام شركتك من القوائم المالية المعتمدة.
B7: 2. Keep one unit for everything (e.g. EGP millions). Enter four balance sheets (the first year is only used for averages) and three years of income and cash flow.
B8: خلّي كل الأرقام بنفس الوحدة (مثلًا مليون جنيه). محتاج 4 ميزانيات (أول سنة للمتوسطات بس) و3 سنين من قائمة الدخل والتدفقات.
B9: 3. Do not type in black cells: they are formulas. Horizontal, Vertical, Ratios and DuPont fill themselves.
B10: ماتكتبش في الخانات السودا، دي معادلات. شيتات Horizontal وVertical وRatios وDuPont بتتحسب لوحدها.
B11: 4. Check row "Balance check" on the Input sheet: it must be zero (or ±0.1 from rounding). If not, a figure is wrong.
B12: راجع سطر Balance check في شيت Input: لازم يطلع صفر (أو ±0.1 من التقريب). لو مش صفر، فيه رقم غلط.
B13: 5. The numbers are not the analysis. For every ratio, write one line: what changed, why, and what it means. See the guide on MBA Platform.
... B24: Independent study aid by Mohamed Elsayed, AI Instructor. Not an official Arab Academy publication, and not investment advice.

Sheet Input
A1: Input · Company: Cleopatra Hospitals Group (example)
A2: Unit: EGP millions · الوحدة: مليون جنيه
A3: Company name / اسم الشركة: | C3: Cleopatra Hospitals Group
A4: Item | B4: البند | C4: 2022 | D4: 2023 | E4: 2024 | F4: 2025 | G4: Note / ملاحظة
A5: INCOME STATEMENT · قائمة الدخل
A6: Revenue | B6: الإيرادات | D6: 3595 | E6: 5420.4 | F6: 7227.3 | G6: 2022: balance sheet only (used for 2023 averages)
A7: Cost of revenue (COGS) | B7: تكلفة الإيرادات | D7: 2387 | E7: 3407.1 | F7: 4368.8 | G7: Enter as a positive number
A8: Gross profit | B8: مجمل الربح | D8: =D6-D7 -> 1208 | E8: =E6-E7 -> 2013.3 | F8: =F6-F7 -> 2858.5
A9: G&A and other operating expenses | B9: مصروفات إدارية وتشغيلية | D9: 545 | E9: 800.6 | F9: 1341.1 | G9: Includes expected credit losses
A10: Operating profit (EBIT) | B10: الربح التشغيلي | D10: 649 | E10: 1162.8 | F10: 1499.8 | G10: As reported (other income/expenses included)
A11: Interest (finance) expense | B11: مصروف الفوائد | D11: 70 | E11: 122 | F11: 227.3
A12: Profit before tax | B12: الربح قبل الضرائب | D12: 608 | E12: 1083.7 | F12: 1319.1
A13: Net profit after tax | B13: صافي الربح بعد الضرائب | D13: 469 | E13: 817 | F13: 967.9 | G13: Total, incl. non-controlling interests
A14: Depreciation & amortization | B14: الإهلاك والاستهلاك | D14: 152.4 | E14: 184.3 | F14: 219.7 | G14: From the cash flow statement
A15: EPS (as reported) | B15: ربحية السهم | E15: 0.39 | F15: 0.46 | G15: EGP per share; not in the FY2023 release
A16: BALANCE SHEET · الميزانية
A17: Cash and cash equivalents | B17: النقدية وما في حكمها | C17: 247.2 | D17: 357.9 | E17: 473.2 | F17: 547.5
A18: Accounts receivable (net) | B18: الذمم المدينة (العملاء) | C18: 486.3 | D18: 648.5 | E18: 1046.8 | F18: 1241.5
A19: Inventory | B19: المخزون | C19: 108 | D19: 292 | E19: 320.5 | F19: 281.3
A20: Other current assets | B20: أصول متداولة أخرى | C20: 275 | D20: 468.7 | E20: 617.7 | F20: 293 | G20: Other receivables, prepayments, etc.
A21: Total current assets | B21: إجمالي الأصول المتداولة | C21: =C17+C18+C19+C20 -> 1116.5 | D21: =D17+D18+D19+D20 -> 1767.1 | E21: =E17+E18+E19+E20 -> 2458.2 | F21: =F17+F18+F19+F20 -> 2363.3
A22: Fixed assets (PP&E) | B22: الأصول الثابتة | C22: 1567.3 | D22: 2176.6 | E22: 4642.2 | F22: 7072.9
A23: Other non-current assets | B23: أصول غير متداولة أخرى | C23: 580.6 | D23: 544.3 | E23: 489.4 | F23: 805 | G23: Intangibles, investments, projects, etc.
A24: Total non-current assets | B24: إجمالي الأصول غير المتداولة | C24: =C22+C23 -> 2147.9 | D24: =D22+D23 -> 2720.9 | E24: =E22+E23 -> 5131.6 | F24: =F22+F23 -> 7877.9
A25: TOTAL ASSETS | B25: إجمالي الأصول | C25: =C21+C24 -> 3264.4 | D25: =D21+D24 -> 4488 | E25: =E21+E24 -> 7589.8 | F25: =F21+F24 -> 10241.2
A26: Short-term borrowings | B26: قروض قصيرة الأجل | C26: 244.5 | D26: 318.9 | E26: 439.7 | F26: 842.4 | G26: Incl. current portion of long-term loans
A27: Payables and other current liabilities | B27: دائنون والتزامات متداولة أخرى | C27: 659.6 | D27: 1112.2 | E27: 1884.8 | F27: 2467.9
A28: Total current liabilities | B28: إجمالي الالتزامات المتداولة | C28: =C26+C27 -> 904.1 | D28: =D26+D27 -> 1431.1 | E28: =E26+E27 -> 2324.5 | F28: =F26+F27 -> 3310.3
A29: Long-term borrowings | B29: قروض طويلة الأجل | C29: 88 | D29: 423 | E29: 1908.8 | F29: 2684.7
A30: Other non-current liabilities | B30: التزامات غير متداولة أخرى | C30: 244.9 | D30: 187.7 | E30: 178.7 | F30: 205.9 | G30: Leases, deferred tax, etc.
A31: Total non-current liabilities | B31: إجمالي الالتزامات غير المتداولة | C31: =C29+C30 -> 332.9 | D31: =D29+D30 -> 610.7 | E31: =E29+E30 -> 2087.5 | F31: =F29+F30 -> 2890.6
A32: TOTAL LIABILITIES | B32: إجمالي الالتزامات | C32: =C28+C31 -> 1237 | D32: =D28+D31 -> 2041.8 | E32: =E28+E31 -> 4412 | F32: =F28+F31 -> 6200.9
A33: Equity attributable to parent | B33: حقوق ملكية الشركة الأم | C33: 1878.9 | D33: 2249.8 | E33: 2899.6 | F33: 3622.3
A34: Non-controlling interests | B34: حقوق الأقلية | C34: 148.4 | D34: 196.5 | E34: 278.2 | F34: 418
A35: TOTAL EQUITY | B35: إجمالي حقوق الملكية | C35: =C33+C34 -> 2027.3 | D35: =D33+D34 -> 2446.3 | E35: =E33+E34 -> 3177.8 | F35: =F33+F34 -> 4040.3
A36: Balance check (should be 0) | B36: مراجعة التوازن (لازم صفر) | C36: =C25-C32-C35 -> 0.1 | D36: =D25-D32-D35 -> -0.1 | E36: =E25-E32-E35 -> 0 | F36: =F25-F32-F35 -> 0 | G36: ±0.1 is rounding
A37: CASH FLOW STATEMENT · قائمة التدفقات النقدية
A38: Net cash from operating activities | B38: صافي التدفق من التشغيل | D38: 521.6 | E38: 1500 | F38: 1891.9 | G38: 2024–2025 from audited FS
A39: Net cash from investing activities | B39: صافي التدفق من الاستثمار | D39: -797.7 | E39: -2665.8 | F39: -2599.3 | G39: Negative = cash spent
A40: Net cash from financing activities | B40: صافي التدفق من التمويل | D40: 291.1 | E40: 1281.2 | F40: 784.2
...

Sheet Horizontal
A1: Horizontal analysis · التحليل الأفقي
A2: Change from the previous year: (This year − Last year) ÷ Last year. Lecture 02.
A4: Item | B4: البند | C4: 2023 vs 2022 | D4: 2024 vs 2023 | E4: 2025 vs 2024 | F4: Your comment · تعليقك
A5: Revenue | B5: الإيرادات | C5: =IF(OR(Input!C6="",Input!C6=0),"n/a",(Input!D6-Input!C6)/ABS(Input!C6)) -> n/a | D5: =IF(OR(Input!D6="",Input!D6=0),"n/a",(Input!E6-Input!D6)/ABS(Input!D6)) -> 0.50776078 | E5: =IF(OR(Input!E6="",Input!E6=0),"n/a",(Input!F6-Input!E6)/ABS(Input!E6)) -> 0.33335178
A6: Cost of revenue (COGS) | B6: تكلفة الإيرادات | C6: =IF(OR(Input!C7="",Input!C7=0),"n/a",(Input!D7-Input!C7)/ABS(Input!C7)) -> n/a | D6: =IF(OR(Input!D7="",Input!D7=0),"n/a",(Input!E7-Input!D7)/ABS(Input!D7)) -> 0.42735651 | E6: =IF(OR(Input!E7="",Input!E7=0),"n/a",(Input!F7-Input!E7)/ABS(Input!E7)) -> 0.28226351
A7: Gross profit | B7: مجمل الربح | C7: =IF(OR(Input!C8="",Input!C8=0),"n/a",(Input!D8-Input!C8)/ABS(Input!C8)) -> n/a | D7: =IF(OR(Input!D8="",Input!D8=0),"n/a",(Input!E8-Input!D8)/ABS(Input!D8)) -> 0.66663907 | E7: =IF(OR(Input!E8="",Input!E8=0),"n/a",(Input!F8-Input!E8)/ABS(Input!E8)) -> 0.41980827
A8: G&A and other operating expenses | B8: مصروفات إدارية وتشغيلية | C8: =IF(OR(Input!C9="",Input!C9=0),"n/a",(Input!D9-Input!C9)/ABS(Input!C9)) -> n/a | D8: =IF(OR(Input!D9="",Input!D9=0),"n/a",(Input!E9-Input!D9)/ABS(Input!D9)) -> 0.46899083 | E8: =IF(OR(Input!E9="",Input!E9=0),"n/a",(Input!F9-Input!E9)/ABS(Input!E9)) -> 0.67511866
A9: Operating profit (EBIT) | B9: الربح التشغيلي | C9: =IF(OR(Input!C10="",Input!C10=0),"n/a",(Input!D10-Input!C10)/ABS(Input!C10)) -> n/a | D9: =IF(OR(Input!D10="",Input!D10=0),"n/a",(Input!E10-Input!D10)/ABS(Input!D10)) -> 0.79167951 | E9: =IF(OR(Input!E10="",Input!E10=0),"n/a",(Input!F10-Input!E10)/ABS(Input!E10)) -> 0.28981768
A10: Interest (finance) expense | B10: مصروف الفوائد | C10: =IF(OR(Input!C11="",Input!C11=0),"n/a",(Input!D11-Input!C11)/ABS(Input!C11)) -> n/a | D10: =IF(OR(Input!D11="",Input!D11=0),"n/a",(Input!E11-Input!D11)/ABS(Input!D11)) -> 0.74285714 | E10: =IF(OR(Input!E11="",Input!E11=0),"n/a",(Input!F11-Input!E11)/ABS(Input!E11)) -> 0.86311475
A11: Net profit after tax | B11: صافي الربح بعد الضرائب | C11: =IF(OR(Input!C13="",Input!C13=0),"n/a",(Input!D13-Input!C13)/ABS(Input!C13)) -> n/a | D11: =IF(OR(Input!D13="",Input!D13=0),"n/a",(Input!E13-Input!D13)/ABS(Input!D13)) -> 0.74200426 | E11: =IF(OR(Input!E13="",Input!E13=0),"n/a",(Input!F13-Input!E13)/ABS(Input!E13)) -> 0.18470012
A12: Cash and cash equivalents | B12: النقدية وما في حكمها | C12: =IF(OR(Input!C17="",Input!C17=0),"n/a",(Input!D17-Input!C17)/ABS(Input!C17)) -> 0.44781553 | D12: =IF(OR(Input!D17="",Input!D17=0),"n/a",(Input!E17-Input!D17)/ABS(Input!D17)) -> 0.32215703 | E12: =IF(OR(Input!E17="",Input!E17=0),"n/a",(Input!F17-Input!E17)/ABS(Input!E17)) -> 0.15701606
A13: Accounts receivable (net) | B13: الذمم المدينة (العملاء) | C13: =IF(OR(Input!C18="",Input!C18=0),"n/a",(Input!D18-Input!C18)/ABS(Input!C18)) -> 0.33353897 | D13: =IF(OR(Input!D18="",Input!D18=0),"n/a",(Input!E18-Input!D18)/ABS(Input!D18)) -> 0.61418658 | E13: =IF(OR(Input!E18="",Input!E18=0),"n/a",(Input!F18-Input!E18)/ABS(Input!E18)) -> 0.18599541
A14: Inventory | B14: المخزون | C14: =IF(OR(Input!C19="",Input!C19=0),"n/a",(Input!D19-Input!C19)/ABS(Input!C19)) -> 1.7037037 | D14: =IF(OR(Input!D19="",Input!D19=0),"n/a",(Input!E19-Input!D19)/ABS(Input!D19)) -> 0.09760274 | E14: =IF(OR(Input!E19="",Input!E19=0),"n/a",(Input!F19-Input!E19)/ABS(Input!E19)) -> -0.12230889
A15: Fixed assets (PP&E) | B15: الأصول الثابتة | C15: =IF(OR(Input!C22="",Input!C22=0),"n/a",(Input!D22-Input!C22)/ABS(Input!C22)) -> 0.38875774 | D15: =IF(OR(Input!D22="",Input!D22=0),"n/a",(Input!E22-Input!D22)/ABS(Input!D22)) -> 1.1327759 | E15: =IF(OR(Input!E22="",Input!E22=0),"n/a",(Input!F22-Input!E22)/ABS(Input!E22)) -> 0.5236095
A16: TOTAL ASSETS | B16: إجمالي الأصول | C16: =IF(OR(Input!C25="",Input!C25=0),"n/a",(Input!D25-Input!C25)/ABS(Input!C25)) -> 0.37483152 | D16: =IF(OR(Input!D25="",Input!D25=0),"n/a",(Input!E25-Input!D25)/ABS(Input!D25)) -> 0.69113191 | E16: =IF(OR(Input!E25="",Input!E25=0),"n/a",(Input!F25-Input!E25)/ABS(Input!E25)) -> 0.34933727
A17: Short-term borrowings | B17: قروض قصيرة الأجل | C17: =IF(OR(Input!C26="",Input!C26=0),"n/a",(Input!D26-Input!C26)/ABS(Input!C26)) -> 0.30429448 | D17: =IF(OR(Input!D26="",Input!D26=0),"n/a",(Input!E26-Input!D26)/ABS(Input!D26)) -> 0.37880213 | E17: =IF(OR(Input!E26="",Input!E26=0),"n/a",(Input!F26-Input!E26)/ABS(Input!E26)) -> 0.91585172
A18: Long-term borrowings | B18: قروض طويلة الأجل | C18: =IF(OR(Input!C29="",Input!C29=0),"n/a",(Input!D29-Input!C29)/ABS(Input!C29)) -> 3.8068182 | D18: =IF(OR(Input!D29="",Input!D29=0),"n/a",(Input!E29-Input!D29)/ABS(Input!D29)) -> 3.5125296 | E18: =IF(OR(Input!E29="",Input!E29=0),"n/a",(Input!F29-Input!E29)/ABS(Input!E29)) -> 0.40648575
A19: TOTAL LIABILITIES | B19: إجمالي الالتزامات | C19: =IF(OR(Input!C32="",Input!C32=0),"n/a",(Input!D32-Input!C32)/ABS(Input!C32)) -> 0.65060631 | D19: =IF(OR(Input!D32="",Input!D32=0),"n/a",(Input!E32-Input!D32)/ABS(Input!D32)) -> 1.1608385 | E19: =IF(OR(Input!E32="",Input!E32=0),"n/a",(Input!F32-Input!E32)/ABS(Input!E32)) -> 0.40546238
A20: TOTAL EQUITY | B20: إجمالي حقوق الملكية | C20: =IF(OR(Input!C35="",Input!C35=0),"n/a",(Input!D35-Input!C35)/ABS(Input!C35)) -> 0.20667883 | D20: =IF(OR(Input!D35="",Input!D35=0),"n/a",(Input!E35-Input!D35)/ABS(Input!D35)) -> 0.29902301 | E20: =IF(OR(Input!E35="",Input!E35=0),"n/a",(Input!F35-Input!E35)/ABS(Input!E35)) -> 0.27141419
A21: Net cash from operating activities | B21: صافي التدفق من التشغيل | C21: =IF(OR(Input!C38="",Input!C38=0),"n/a",(Input!D38-Input!C38)/ABS(Input!C38)) -> n/a | D21: =IF(OR(Input!D38="",Input!D38=0),"n/a",(Input!E38-Input!D38)/ABS(Input!D38)) -> 1.8757669 | E21: =IF(OR(Input!E38="",Input!E38=0),"n/a",(Input!F38-Input!E38)/ABS(Input!E38)) -> 0.26126667

Sheet Vertical
A1: Vertical analysis · التحليل الرأسي
A2: Income items as % of revenue; balance sheet items as % of total assets. Lecture 02.
A4: Item | B4: البند | C4: 2023 | D4: 2024 | E4: 2025 | F4: Your comment · تعليقك
A5: Cost of revenue (COGS) / Revenue | B5: تكلفة الإيرادات | C5: =Input!D7/Input!D6 -> 0.66397775 | D5: =Input!E7/Input!E6 -> 0.62856985 | E5: =Input!F7/Input!F6 -> 0.60448577
A6: Gross profit / Revenue | B6: مجمل الربح | C6: =Input!D8/Input!D6 -> 0.33602225 | D6: =Input!E8/Input!E6 -> 0.37143015 | E6: =Input!F8/Input!F6 -> 0.39551423
A7: G&A and other operating expenses / Revenue | B7: مصروفات إدارية وتشغيلية | C7: =Input!D9/Input!D6 -> 0.15159944 | D7: =Input!E9/Input!E6 -> 0.14770128 | E7: =Input!F9/Input!F6 -> 0.18556031
A8: Operating profit (EBIT) / Revenue | B8: الربح التشغيلي | C8: =Input!D10/Input!D6 -> 0.18052851 | D8: =Input!E10/Input!E6 -> 0.21452291 | E8: =Input!F10/Input!F6 -> 0.20751871
A9: Interest (finance) expense / Revenue | B9: مصروف الفوائد | C9: =Input!D11/Input!D6 -> 0.019471488 | D9: =Input!E11/Input!E6 -> 0.022507564 | E9: =Input!F11/Input!F6 -> 0.031450196
A10: Net profit after tax / Revenue | B10: صافي الربح بعد الضرائب | C10: =Input!D13/Input!D6 -> 0.13045897 | D10: =Input!E13/Input!E6 -> 0.15072688 | E10: =Input!F13/Input!F6 -> 0.13392277
A12: Cash and cash equivalents / Total assets | B12: النقدية وما في حكمها | C12: =Input!D17/Input!D25 -> 0.079745989 | D12: =Input!E17/Input!E25 -> 0.062346834 | E12: =Input!F17/Input!F25 -> 0.053460532
A13: Accounts receivable (net) / Total assets | B13: الذمم المدينة (العملاء) | C13: =Input!D18/Input!D25 -> 0.14449643 | D13: =Input!E18/Input!E25 -> 0.13792195 | E13: =Input!F18/Input!F25 -> 0.12122603
A14: Inventory / Total assets | B14: المخزون | C14: =Input!D19/Input!D25 -> 0.065062389 | D14: =Input!E19/Input!E25 -> 0.042227727 | E14: =Input!F19/Input!F25 -> 0.027467484
A15: Total current assets / Total assets | B15: إجمالي الأصول المتداولة | C15: =Input!D21/Input!D25 -> 0.39373886 | D15: =Input!E21/Input!E25 -> 0.32388205 | E15: =Input!F21/Input!F25 -> 0.23076397
A16: Fixed assets (PP&E) / Total assets | B16: الأصول الثابتة | C16: =Input!D22/Input!D25 -> 0.48498217 | D16: =Input!E22/Input!E25 -> 0.61163667 | E16: =Input!F22/Input!F25 -> 0.69063196
A17: Total non-current assets / Total assets | B17: إجمالي الأصول غير المتداولة | C17: =Input!D24/Input!D25 -> 0.60626114 | D17: =Input!E24/Input!E25 -> 0.67611795 | E17: =Input!F24/Input!F25 -> 0.76923603
A18: Total current liabilities / Total assets | B18: إجمالي الالتزامات المتداولة | C18: =Input!D28/Input!D25 -> 0.31887255 | D18: =Input!E28/Input!E25 -> 0.3062663 | E18: =Input!F28/Input!F25 -> 0.32323361
A19: Total non-current liabilities / Total assets | B19: إجمالي الالتزامات غير المتداولة | C19: =Input!D31/Input!D25 -> 0.13607398 | D19: =Input!E31/Input!E25 -> 0.27504019 | E19: =Input!F31/Input!F25 -> 0.28225208
A20: TOTAL LIABILITIES / Total assets | B20: إجمالي الالتزامات | C20: =Input!D32/Input!D25 -> 0.45494652 | D20: =Input!E32/Input!E25 -> 0.58130649 | E20: =Input!F32/Input!F25 -> 0.60548569
A21: TOTAL EQUITY / Total assets | B21: إجمالي حقوق الملكية | C21: =Input!D35/Input!D25 -> 0.54507576 | D21: =Input!E35/Input!E25 -> 0.41869351 | E21: =Input!F35/Input!F25 -> 0.39451431

Sheet Ratios
A1: Financial ratios · النسب المالية
A2: Averages use (opening + closing) ÷ 2, which is why four balance sheets are needed. Lecture 04.
A4: Ratio | B4: النسبة | C4: 2023 | D4: 2024 | E4: 2025 | F4: Formula · المعادلة | G4: Your comment · تعليقك
A5: LIQUIDITY · السيولة
A6: Current ratio | B6: نسبة التداول | C6: =Input!D21/Input!D28 -> 1.2347844 | D6: =Input!E21/Input!E28 -> 1.0575177 | E6: =Input!F21/Input!F28 -> 0.71392321 | F6: Current assets ÷ Current liabilities
A7: Quick ratio (acid-test) | B7: نسبة السيولة السريعة | C7: =(Input!D21-Input!D19)/Input!D28 -> 1.0307456 | D7: =(Input!E21-Input!E19)/Input!E28 -> 0.91963863 | E7: =(Input!F21-Input!F19)/Input!F28 -> 0.62894602 | F7: (Current assets − Inventory) ÷ Current liabilities
A8: Cash ratio | B8: نسبة النقدية | C8: =Input!D17/Input!D28 -> 0.25008735 | D8: =Input!E17/Input!E28 -> 0.20357066 | E8: =Input!F17/Input!F28 -> 0.16539286 | F8: Cash ÷ Current liabilities
A9: ACTIVITY (EFFICIENCY) · النشاط (الكفاءة)
A10: Inventory turnover | B10: معدل دوران المخزون | C10: =Input!D7/((Input!C19+Input!D19)/2) -> 11.935 | D10: =Input!E7/((Input!D19+Input!E19)/2) -> 11.125224 | E10: =Input!F7/((Input!E19+Input!F19)/2) -> 14.519109 | F10: COGS ÷ Average inventory
A11: Days inventory | B11: أيام المخزون | C11: =365/(Input!D7/((Input!C19+Input!D19)/2)) -> 30.582321 | D11: =365/(Input!E7/((Input!D19+Input!E19)/2)) -> 32.808327 | E11: =365/(Input!F7/((Input!E19+Input!F19)/2)) -> 25.139283 | F11: 365 ÷ Inventory turnover
A12: Receivables turnover | B12: معدل دوران الذمم المدينة | C12: =Input!D6/((Input!C18+Input!D18)/2) -> 6.3359182 | D12: =Input!E6/((Input!D18+Input!E18)/2) -> 6.3946204 | E12: =Input!F6/((Input!E18+Input!F18)/2) -> 6.3167417 | F12: Revenue ÷ Average receivables (credit sales not disclosed)
A13: Average collection period | B13: متوسط فترة التحصيل | C13: =365/(Input!D6/((Input!C18+Input!D18)/2)) -> 57.608067 | D13: =365/(Input!E6/((Input!D18+Input!E18)/2)) -> 57.079228 | E13: =365/(Input!F6/((Input!E18+Input!F18)/2)) -> 57.782955 | F13: 365 ÷ Receivables turnover
A14: Fixed asset turnover | B14: معدل دوران الأصول الثابتة | C14: =Input!D6/((Input!C22+Input!D22)/2) -> 1.9204573 | D14: =Input!E6/((Input!D22+Input!E22)/2) -> 1.5898399 | E14: =Input!F6/((Input!E22+Input!F22)/2) -> 1.2338435 | F14: Revenue ÷ Average fixed assets
A15: Total asset turnover | B15: معدل دوران إجمالي الأصول | C15: =Input!D6/((Input!C25+Input!D25)/2) -> 0.92745472 | D15: =Input!E6/((Input!D25+Input!E25)/2) -> 0.89758069 | E15: =Input!F6/((Input!E25+Input!F25)/2) -> 0.81064438 | F15: Revenue ÷ Average total assets
A16: PROFITABILITY · الربحية
A17: Gross profit margin | B17: هامش مجمل الربح | C17: =Input!D8/Input!D6 -> 0.33602225 | D17: =Input!E8/Input!E6 -> 0.37143015 | E17: =Input!F8/Input!F6 -> 0.39551423 | F17: Gross profit ÷ Revenue
A18: Operating (EBIT) margin | B18: هامش الربح التشغيلي | C18: =Input!D10/Input!D6 -> 0.18052851 | D18: =Input!E10/Input!E6 -> 0.21452291 | E18: =Input!F10/Input!F6 -> 0.20751871 | F18: EBIT ÷ Revenue
A19: Net profit margin | B19: هامش صافي الربح | C19: =Input!D13/Input!D6 -> 0.13045897 | D19: =Input!E13/Input!E6 -> 0.15072688 | E19: =Input!F13/Input!F6 -> 0.13392277 | F19: Net profit ÷ Revenue
A20: ROA · Return on Assets | B20: العائد على الأصول | C20: =Input!D13/((Input!C25+Input!D25)/2) -> 0.12099479 | D20: =Input!E13/((Input!D25+Input!E25)/2) -> 0.13528954 | E20: =Input!F13/((Input!E25+Input!F25)/2) -> 0.10856374 | F20: Net profit ÷ Average total assets
A21: ROE · Return on Equity | B21: العائد على حقوق الملكية | C21: =Input!D13/((Input!C35+Input!D35)/2) -> 0.20967454 | D21: =Input!E13/((Input!D35+Input!E35)/2) -> 0.29053537 | E21: =Input!F13/((Input!E35+Input!F35)/2) -> 0.26818692 | F21: Net profit ÷ Average total equity
A22: EPS · Earnings Per Share | B22: ربحية السهم | C22: =IF(Input!D15="","n/a",Input!D15) -> n/a | D22: =IF(Input!E15="","n/a",Input!E15) -> 0.39 | E22: =IF(Input!F15="","n/a",Input!F15) -> 0.46 | F22: As reported (Net profit to parent − pref. dividends) ÷ shares
A23: LEVERAGE · الرافعة المالية
A24: Debt ratio | B24: نسبة المديونية | C24: =Input!D32/Input!D25 -> 0.45494652 | D24: =Input!E32/Input!E25 -> 0.58130649 | E24: =Input!F32/Input!F25 -> 0.60548569 | F24: Total liabilities ÷ Total assets
A25: Borrowings to assets | B25: القروض إلى الأصول | C25: =(Input!D26+Input!D29)/Input!D25 -> 0.16530749 | D25: =(Input!E26+Input!E29)/Input!E25 -> 0.30942844 | E25: =(Input!F26+Input!F29)/Input!F25 -> 0.344403 | F25: (Short + long-term borrowings) ÷ Total assets
A26: Debt-to-equity (D/E) | B26: الديون إلى حقوق الملكية | C26: =Input!D32/Input!D35 -> 0.83464824 | D26: =Input!E32/Input!E35 -> 1.3883819 | E26: =Input!F32/Input!F35 -> 1.5347623 | F26: Total liabilities ÷ Total equity
A27: Interest coverage (times interest earned) | B27: معدل تغطية الفوائد | C27: =Input!D10/Input!D11 -> 9.2714286 | D27: =Input!E10/Input!E11 -> 9.5311475 | E27: =Input!F10/Input!F11 -> 6.5983282 | F27: EBIT ÷ Interest expense
A28: CASH FLOW QUALITY · جودة التدفقات
A29: Operating cash flow ÷ Net profit | B29: التدفق التشغيلي ÷ صافي الربح | C29: =Input!D38/Input!D13 -> 1.1121535 | D29: =Input!E38/Input!E13 -> 1.8359853 | E29: =Input!F38/Input!F13 -> 1.9546441 | F29: Above 1: profit is backed by cash
A30: Operating + investing cash flow | B30: التدفق التشغيلي + الاستثماري | C30: =Input!D38+Input!D39 -> -276.1 | D30: =Input!E38+Input!E39 -> -1165.8 | E30: =Input!F38+Input!F39 -> -707.4 | F30: Negative: investment needs outside financing

Sheet DuPont
A1: DuPont analysis · تحليل ديبونت
A2: ROE = Net profit margin × Total asset turnover × Equity multiplier. Lecture 02.
A4: Component | B4: المكوّن | C4: 2023 | D4: 2024 | E4: 2025 | F4: Formula · المعادلة | G4: Your comment · تعليقك
A5: Net profit margin | B5: هامش صافي الربح | C5: =Input!D13/Input!D6 -> 0.13045897 | D5: =Input!E13/Input!E6 -> 0.15072688 | E5: =Input!F13/Input!F6 -> 0.13392277 | F5: Net profit ÷ Revenue
A6: Total asset turnover | B6: دوران إجمالي الأصول | C6: =Input!D6/((Input!C25+Input!D25)/2) -> 0.92745472 | D6: =Input!E6/((Input!D25+Input!E25)/2) -> 0.89758069 | E6: =Input!F6/((Input!E25+Input!F25)/2) -> 0.81064438 | F6: Revenue ÷ Average total assets
A7: Equity multiplier | B7: مضاعف حقوق الملكية | C7: =((Input!C25+Input!D25)/2)/((Input!C35+Input!D35)/2) -> 1.732922 | D7: =((Input!D25+Input!E25)/2)/((Input!D35+Input!E35)/2) -> 2.147508 | E7: =((Input!E25+Input!F25)/2)/((Input!E35+Input!F35)/2) -> 2.4703177 | F7: Average total assets ÷ Average equity
A8: ROE (DuPont) | B8: العائد على حقوق الملكية | C8: =C5*C6*C7 -> 0.20967454 | D8: =D5*D6*D7 -> 0.29053537 | E8: =E5*E6*E7 -> 0.26818692 | F8: Margin × Turnover × Multiplier
A9: ROE (direct, from Ratios) | B9: العائد المباشر للمقارنة | C9: =Ratios!C21 -> 0.20967454 | D9: =Ratios!D21 -> 0.29053537 | E9: =Ratios!E21 -> 0.26818692 | F9: Must equal the line above

Sheet Checklist
B1: Before you submit · قبل ما تسلّم
A3: ☐ | B3: Company chosen; 3 years of audited statements downloaded | C3: اخترت الشركة ونزّلت قوائم 3 سنين معتمدة
A4: ☐ | B4: All figures in one unit and the balance check is zero | C4: كل الأرقام بنفس الوحدة ومراجعة التوازن صفر
A5: ☐ | B5: Company profile: what it does, size, market, competitors | C5: نبذة عن الشركة: بتعمل إيه وحجمها وسوقها ومنافسينها
A6: ☐ | B6: Horizontal analysis with comments on the big changes | C6: تحليل أفقي مع تعليق على التغيرات الكبيرة
A7: ☐ | B7: Vertical analysis with comments on the structure | C7: تحليل رأسي مع تعليق على الهيكل
A8: ☐ | B8: Ratios: liquidity, activity, profitability, leverage | C8: النسب: سيولة ونشاط وربحية ومديونية
A9: ☐ | B9: Trend (over years) and, if possible, a competitor or industry comparison | C9: مقارنة على السنين، ومع منافس أو متوسط الصناعة لو متاح
A10: ☐ | B10: DuPont: what drives ROE | C10: ديبونت: إيه اللي محرّك العائد على حقوق الملكية
A11: ☐ | B11: Cash flow: is profit turning into cash? how is growth financed? | C11: التدفقات: الربح بيتحول كاش؟ والتوسع ممول منين؟
A12: ☐ | B12: Conclusion: strengths, weaknesses, risks, recommendations | C12: الخلاصة: نقاط القوة والضعف والمخاطر والتوصيات
A13: ☐ | B13: Sources cited (annual report, page numbers) | C13: المصادر مكتوبة (التقرير السنوي وأرقام الصفحات)
